Workbook

Sheet Summary of Takeoff
A1: Name of Work:-
A2: Proposed Construction of Sunil Mahant Residence
A3: Name of Sub Work:-
A4: Residential Building
A5: SUMMARY OF QUANTITIES
A6: Sr No. | B6: Category of Civil/Finishing Work | C6: Quantity Takeoff | D6: Unit
A7: 1.0 | B7: Excavation Works | C7: ='Takeoff Measurements'!H10 | D7: Cu.M.
A8: 2.0 | B8: Plain Cement Concrete (PCC) | C8: ='Takeoff Measurements'!H16 | D8: Cu.M.
A9: 3.0 | B9: Reinforced Cement Concrete (RCC) | C9: ='Takeoff Measurements'!H40 | D9: Cu.M.
A10: 4.0 | B10: Brickwork & Partition Masonry | C10: ='Takeoff Measurements'!H85 | D10: Cu.M.
A11: 5.0 | B11: Plastering Works | C11: ='Takeoff Measurements'!H177 | D11: Sqm
A12: 6.0 | B12: Flooring & Finishes | C12: ='Takeoff Measurements'!H250 | D12: Sqm

Sheet Takeoff Measurements
A1: Name of Work:-
A2: Proposed Construction of Sunil Mahant Residence
A3: Name of Sub Work:-
A4: Residential Building
A5: DETAILED TAKE-OFF MEASUREMENTS
A6: 1.0 | B6: Excavation Works | C6: Detailed Quantity Takeoff for Excavation Works | I6: Cubic Metre
B8: Description of Measurement | D8: No. | E8: Length | F8: Width | G8: Height | H8: Quantity | I8: Unit
B9: Footing base excavation: F1 | D9: 9 | E9: 1.2 | F9: 1.2 | G9: 1.5 | H9: =D9*E9*F9*G9 | I9: Cu.M.
B10: Net Quantity | H10: =ROUND(SUM(H9:H9), 2) | I10: Cu.M.
A12: 2.0 | B12: Plain Cement Concrete (PCC) | C12: Detailed Quantity Takeoff for Plain Cement Concrete (PCC) | I12: Cubic Metre
B14: Description of Measurement | D14: No. | E14: Length | F14: Width | G14: Height | H14: Quantity | I14: Unit
B15: PCC under footing: F1 | D15: 9 | E15: 1.2 | F15: 1.2 | G15: 0.1 | H15: =D15*E15*F15*G15 | I15: Cu.M.
B16: Net Quantity | H16: =ROUND(SUM(H15:H15), 2) | I16: Cu.M.
A18: 3.0 | B18: Reinforced Cement Concrete (RCC) | C18: Detailed Quantity Takeoff for Reinforced Cement Concrete (RCC) | I18: Cubic Metre
B20: Description of Measurement | D20: No. | E20: Length | F20: Width | G20: Height | H20: Quantity | I20: Unit
B21: RCC Footing: F1 | D21: 9 | E21: 1.2 | F21: 1.2 | G21: 0.4 | H21: =D21*E21*F21*G21 | I21: Cu.M.
B22: Columns RCC C1 (Rectangle) | D22: 9 | E22: 0.23 | F22: 0.23 | G22: 10.5 | H22: =D22*E22*F22*G22 | I22: Cu.M.
B23: Beams RCC: B1 | D23: 9 | E23: 4.5 | F23: 0.23 | G23: 0.45 | H23: =D23*E23*F23*G23 | I23: Cu.M.
B24: Ground Floor - Slabs RCC | D24: 1 | E24: 20.96785 | F24: 1 | G24: 0.12 | H24: =D24*E24*F24*G24 | I24: Cu.M.
B25: Ground Floor - Staircase Waist Slab RCC | D25: 1 | E25: 5.25 | F25: 1 | G25: 0.12 | H25: =D25*E25*F25*G25 | I25: Cu.M.
B26: Ground Floor - Staircase Steps Concrete | D26: 9 | E26: 0.25 | F26: 1 | G26: 0.15 | H26: =D26*E26*F26*G26 | I26: Cu.M.
B27: Ground Floor - Staircase Midlanding RCC | D27: 1 | E27: 2.1 | F27: 1.05 | G27: 0.12 | H27: =D27*E27*F27*G27 | I27: Cu.M.
B28: First Floor - Slabs RCC | D28: 1 | E28: 69.571625 | F28: 1 | G28: 0.12 | H28: =D28*E28*F28*G28 | I28: Cu.M.
B29: First Floor - Staircase Waist Slab RCC | D29: 1 | E29: 5.25 | F29: 1 | G29: 0.12 | H29: =D29*E29*F29*G29 | I29: Cu.M.
B30: First Floor - Staircase Steps Concrete | D30: 9 | E30: 0.25 | F30: 1 | G30: 0.15 | H30: =D30*E30*F30*G30 | I30: Cu.M.
B31: First Floor - Staircase Midlanding RCC | D31: 1 | E31: 2.1 | F31: 1.05 | G31: 0.12 | H31: =D31*E31*F31*G31 | I31: Cu.M.
B32: Second Floor - Slabs RCC | D32: 1 | E32: 67.6283 | F32: 1 | G32: 0.12 | H32: =D32*E32*F32*G32 | I32: Cu.M.
... B39: Terrace Floor - Staircase Midlanding RCC | D39: 1 | E39: 2.1 | F39: 1.05 | G39: 0.12 | H39: =D39*E39*F39*G39 | I39: Cu.M.
B40: Net Quantity | H40: =ROUND(SUM(H21:H39), 2) | I40: Cu.M.
A42: 4.0 | B42: Brickwork & Partition Masonry | C42: Detailed Quantity Takeoff for Brickwork & Partition Masonry | I42: Cubic Metre
B44: Description of Measurement | D44: No. | E44: Length | F44: Width | G44: Height | H44: Quantity | I44: Unit
B45: Ground Floor - Outer walls brickwork | D45: 1 | E45: 18.47 | F45: 0.23 | G45: 2.88 | H45: =D45*E45*F45*G45 | I45: Cu.M.
B46: Ground Floor - Inner partition brickwork | D46: 1 | E46: 6.21 | F46: 0.115 | G46: 2.88 | H46: =D46*E46*F46*G46 | I46: Cu.M.
B47: Deduction - Ground Floor - Office Door | D47: -1 | E47: 0.9 | F47: 0.23 | G47: 2.1 | H47: =D47*E47*F47*G47 | I47: Cu.M.
B48: Deduction - Ground Floor - Office Window | D48: -1 | E48: 1.5 | F48: 0.23 | G48: 1.5 | H48: =D48*E48*F48*G48 | I48: Cu.M.
B49: Deduction - Ground Floor - Toilet Door | D49: -1 | E49: 0.75 | F49: 0.115 | G49: 2.1 | H49: =D49*E49*F49*G49 | I49: Cu.M.
B50: Deduction - Ground Floor - Toilet Window | D50: -1 | E50: 0.6 | F50: 0.115 | G50: 0.6 | H50: =D50*E50*F50*G50 | I50: Cu.M.
B51: Deduction - Ground Floor - Store Door | D51: -1 | E51: 0.9 | F51: 0.23 | G51: 2.1 | H51: =D51*E51*F51*G51 | I51: Cu.M.
B52: First Floor - Outer walls brickwork | D52: 1 | E52: 33.65 | F52: 0.23 | G52: 2.88 | H52: =D52*E52*F52*G52 | I52: Cu.M.
B53: First Floor - Inner partition brickwork | D53: 1 | E53: 22.9 | F53: 0.115 | G53: 2.88 | H53: =D53*E53*F53*G53 | I53: Cu.M.
...
